2025-06-30 19:49:16 [ERROR] <----------------未知错误-------------------->
2025-06-30 19:49:16 [ERROR] <Traceback (most recent call last):
  File "C:\Python\Lib\site-packages\urllib3\connection.py", line 198, in _new_conn
    sock = connection.create_connection(
        (self._dns_host, self.port),
    ...<2 lines>...
        socket_options=self.socket_options,
    )
  File "C:\Python\Lib\site-packages\urllib3\util\connection.py", line 60, in create_connection
    for res in socket.getaddrinfo(host, port, family, socket.SOCK_STREAM):
               ~~~~~~~~~~~~~~~~~~^^^^^^^^^^^^^^^^^^^^^^^^^^^^^^^^^^^^^^^^
  File "C:\Python\Lib\socket.py", line 977, in getaddrinfo
    for res in _socket.getaddrinfo(host, port, family, type, proto, flags):
               ~~~~~~~~~~~~~~~~~~~^^^^^^^^^^^^^^^^^^^^^^^^^^^^^^^^^^^^^^^^
socket.gaierror: [Errno 11001] getaddrinfo failed

The above exception was the direct cause of the following exception:

Traceback (most recent call last):
  File "C:\Python\Lib\site-packages\urllib3\connectionpool.py", line 787, in urlopen
    response = self._make_request(
        conn,
    ...<10 lines>...
        **response_kw,
    )
  File "C:\Python\Lib\site-packages\urllib3\connectionpool.py", line 488, in _make_request
    raise new_e
  File "C:\Python\Lib\site-packages\urllib3\connectionpool.py", line 464, in _make_request
    self._validate_conn(conn)
    ~~~~~~~~~~~~~~~~~~~^^^^^^
  File "C:\Python\Lib\site-packages\urllib3\connectionpool.py", line 1093, in _validate_conn
    conn.connect()
    ~~~~~~~~~~~~^^
  File "C:\Python\Lib\site-packages\urllib3\connection.py", line 704, in connect
    self.sock = sock = self._new_conn()
                       ~~~~~~~~~~~~~~^^
  File "C:\Python\Lib\site-packages\urllib3\connection.py", line 205, in _new_conn
    raise NameResolutionError(self.host, self, e) from e
urllib3.exceptions.NameResolutionError: <urllib3.connection.HTTPSConnection object at 0x00000219F2AB0EC0>: Failed to resolve 'raw.gitcode.com' ([Errno 11001] getaddrinfo failed)

The above exception was the direct cause of the following exception:

Traceback (most recent call last):
  File "C:\Python\Lib\site-packages\requests\adapters.py", line 667, in send
    resp = conn.urlopen(
        method=request.method,
    ...<9 lines>...
        chunked=chunked,
    )
  File "C:\Python\Lib\site-packages\urllib3\connectionpool.py", line 841, in urlopen
    retries = retries.increment(
        method, url, error=new_e, _pool=self, _stacktrace=sys.exc_info()[2]
    )
  File "C:\Python\Lib\site-packages\urllib3\util\retry.py", line 519, in increment
    raise MaxRetryError(_pool, url, reason) from reason  # type: ignore[arg-type]
    ^^^^^^^^^^^^^^^^^^^^^^^^^^^^^^^^^^^^^^^^^^^^^^^^^^^
urllib3.exceptions.MaxRetryError: HTTPSConnectionPool(host='raw.gitcode.com', port=443): Max retries exceeded with url: /Gelon_Stark/ZA/raw/main/updater.json (Caused by NameResolutionError("<urllib3.connection.HTTPSConnection object at 0x00000219F2AB0EC0>: Failed to resolve 'raw.gitcode.com' ([Errno 11001] getaddrinfo failed)"))

During handling of the above exception, another exception occurred:

Traceback (most recent call last):
  File "C:\Users\gelon\Desktop\Pytutorial\ZenlessZoneZero_Automation\updater\ZA_Updater.py", line 51, in __init__
    updater_response = requests.get(url, headers=None)
  File "C:\Python\Lib\site-packages\requests\api.py", line 73, in get
    return request("get", url, params=params, **kwargs)
  File "C:\Python\Lib\site-packages\requests\api.py", line 59, in request
    return session.request(method=method, url=url, **kwargs)
           ~~~~~~~~~~~~~~~^^^^^^^^^^^^^^^^^^^^^^^^^^^^^^^^^^
  File "C:\Python\Lib\site-packages\requests\sessions.py", line 589, in request
    resp = self.send(prep, **send_kwargs)
  File "C:\Python\Lib\site-packages\requests\sessions.py", line 703, in send
    r = adapter.send(request, **kwargs)
  File "C:\Python\Lib\site-packages\requests\adapters.py", line 700, in send
    raise ConnectionError(e, request=request)
requests.exceptions.ConnectionError: HTTPSConnectionPool(host='raw.gitcode.com', port=443): Max retries exceeded with url: /Gelon_Stark/ZA/raw/main/updater.json (Caused by NameResolutionError("<urllib3.connection.HTTPSConnection object at 0x00000219F2AB0EC0>: Failed to resolve 'raw.gitcode.com' ([Errno 11001] getaddrinfo failed)"))

During handling of the above exception, another exception occurred:

Traceback (most recent call last):
  File "C:\Users\gelon\Desktop\Pytutorial\ZenlessZoneZero_Automation\ZA_Main.py", line 761, in run
    update()
    ~~~~~~^^
  File "C:\Users\gelon\Desktop\Pytutorial\ZenlessZoneZero_Automation\ZA_Main.py", line 395, in update
    if CheckUpdate().need_update():
       ~~~~~~~~~~~^^
  File "C:\Users\gelon\Desktop\Pytutorial\ZenlessZoneZero_Automation\updater\ZA_Updater.py", line 62, in __init__
    input('Exception:网络请求超时\n更新未完成！\n程序已经结束，现在可以退出')
    ~~~~~^^^^^^^^^^^^^^^^^^^^^^^^^^^^^^^^^^^^^^^^^^^^^^^^^^^^^^^^^^^^^^^^^^^^
  File "<frozen codecs>", line 322, in decode
KeyboardInterrupt
>
2025-06-30 19:49:16 [WARNING] <程序已经结束，按回车键退出(Enter)>
